Workbook

Sheet Календар
B2: Жовтень | F2: 2026
B3: TikTok · Amber Galbin · 4 відео на тиждень · Пн 09:00 · Ср 21:00 · Пт 21:00 · Нд 11:00
B5: ПОНЕДІЛОК | C5: ВІВТОРОК | D5: СЕРЕДА | E5: ЧЕТВЕР | F5: П’ЯТНИЦЯ | G5: СУБОТА | H5: НЕДІЛЯ
E6: 46296 | F6: 46297 | G6: 46298 | H6: 46299
E7: =IFERROR(VLOOKUP(E6,'Свята'!$A$5:$D$60,4,FALSE),"") | F7: =IFERROR(VLOOKUP(F6,'Свята'!$A$5:$D$60,4,FALSE),"") | G7: =IFERROR(VLOOKUP(G6,'Свята'!$A$5:$D$60,4,FALSE),"") | H7: =IFERROR(VLOOKUP(H6,'Свята'!$A$5:$D$60,4,FALSE),"")
E8: =IFERROR(VLOOKUP(E6,'Свята'!$A$5:$E$60,5,FALSE),"") | F8: =IFERROR(VLOOKUP(F6,'Свята'!$A$5:$E$60,5,FALSE),"") | G8: =IFERROR(VLOOKUP(G6,'Свята'!$A$5:$E$60,5,FALSE),"") | H8: =IFERROR(VLOOKUP(H6,'Свята'!$A$5:$E$60,5,FALSE),"")
B9: 46300 | C9: 46301 | D9: 46302 | E9: 46303 | F9: 46304 | G9: 46305 | H9: 46306
B10: =IFERROR(VLOOKUP(B9,'Свята'!$A$5:$D$60,4,FALSE),"") | C10: =IFERROR(VLOOKUP(C9,'Свята'!$A$5:$D$60,4,FALSE),"") | D10: =IFERROR(VLOOKUP(D9,'Свята'!$A$5:$D$60,4,FALSE),"") | E10: =IFERROR(VLOOKUP(E9,'Свята'!$A$5:$D$60,4,FALSE),"") | F10: =IFERROR(VLOOKUP(F9,'Свята'!$A$5:$D$60,4,FALSE),"") | G10: =IFERROR(VLOOKUP(G9,'Свята'!$A$5:$D$60,4,FALSE),"") | H10: =IFERROR(VLOOKUP(H9,'Свята'!$A$5:$D$60,4,FALSE),"")
B11: 🪨 Камінь у руках · 09:00 Скільки коштує цей камінь? → | C11: =IFERROR(VLOOKUP(C9,'Свята'!$A$5:$E$60,5,FALSE),"") | D11: 🎁 Річ у ділі · 21:00 Завтра День юриста: 3 подарунки для кабінету → | E11: =IFERROR(VLOOKUP(E9,'Свята'!$A$5:$E$60,5,FALSE),"") | F11: 🔨 Як це зроблено · 21:00 Від сирцю до кулона за 15 секунд → | G11: =IFERROR(VLOOKUP(G9,'Свята'!$A$5:$E$60,5,FALSE),"") | H11: 🔥 Вау-масштаб · 11:00 Картина з бурштину, ч.2 →
B12: 46307 | C12: 46308 | D12: 46309 | E12: 46310 | F12: 46311 | G12: 46312 | H12: 46313
B13: =IFERROR(VLOOKUP(B12,'Свята'!$A$5:$D$60,4,FALSE),"") | C13: =IFERROR(VLOOKUP(C12,'Свята'!$A$5:$D$60,4,FALSE),"") | D13: =IFERROR(VLOOKUP(D12,'Свята'!$A$5:$D$60,4,FALSE),"") | E13: =IFERROR(VLOOKUP(E12,'Свята'!$A$5:$D$60,4,FALSE),"") | F13: =IFERROR(VLOOKUP(F12,'Свята'!$A$5:$D$60,4,FALSE),"") | G13: =IFERROR(VLOOKUP(G12,'Свята'!$A$5:$D$60,4,FALSE),"") | H13: =IFERROR(VLOOKUP(H12,'Свята'!$A$5:$D$60,4,FALSE),"")
B14: 🪨 Камінь у руках · 09:00 ASMR: звук бурштину → | C14: =IFERROR(VLOOKUP(C12,'Свята'!$A$5:$E$60,5,FALSE),"") | D14: 🔨 Як це зроблено · 21:00 Як ми робимо статуетку військової техніки → | E14: =IFERROR(VLOOKUP(E12,'Свята'!$A$5:$E$60,5,FALSE),"") | F14: 🎁 Річ у ділі · 21:00 Відповідаю: скільки коштує бурштин? → | G14: =IFERROR(VLOOKUP(G12,'Свята'!$A$5:$E$60,5,FALSE),"") | H14: 🔥 Вау-масштаб · 11:00 День апостола Луки: ікона з бурштину →
B15: 46314 | C15: 46315 | D15: 46316 | E15: 46317 | F15: 46318 | G15: 46319 | H15: 46320
B16: =IFERROR(VLOOKUP(B15,'Свята'!$A$5:$D$60,4,FALSE),"") | C16: =IFERROR(VLOOKUP(C15,'Свята'!$A$5:$D$60,4,FALSE),"") | D16: =IFERROR(VLOOKUP(D15,'Свята'!$A$5:$D$60,4,FALSE),"") | E16: =IFERROR(VLOOKUP(E15,'Свята'!$A$5:$D$60,4,FALSE),"") | F16: =IFERROR(VLOOKUP(F15,'Свята'!$A$5:$D$60,4,FALSE),"") | G16: =IFERROR(VLOOKUP(G15,'Свята'!$A$5:$D$60,4,FALSE),"") | H16: =IFERROR(VLOOKUP(H15,'Свята'!$A$5:$D$60,4,FALSE),"")
B17: 🪨 Камінь у руках · 09:00 Справжній чи підробка? Тест солоною водою → | C17: =IFERROR(VLOOKUP(C15,'Свята'!$A$5:$E$60,5,FALSE),"") | D17: 🔨 Як це зроблено · 21:00 Один день на виробництві за 20 секунд → | E17: =IFERROR(VLOOKUP(E15,'Свята'!$A$5:$E$60,5,FALSE),"") | F17: 🎁 Річ у ділі · 21:00 День ангела Дмитра: іменна ікона в подарунок → | G17: =IFERROR(VLOOKUP(G15,'Свята'!$A$5:$E$60,5,FALSE),"") | H17: 🔥 Вау-масштаб · 11:00 Шахи з бурштину: розставляємо партію →
B18: 46321 | C18: 46322 | D18: 46323 | E18: 46324 | F18: 46325 | G18: 46326
B19: =IFERROR(VLOOKUP(B18,'Свята'!$A$5:$D$60,4,FALSE),"") | C19: =IFERROR(VLOOKUP(C18,'Свята'!$A$5:$D$60,4,FALSE),"") | D19: =IFERROR(VLOOKUP(D18,'Свята'!$A$5:$D$60,4,FALSE),"") | E19: =IFERROR(VLOOKUP(E18,'Свята'!$A$5:$D$60,4,FALSE),"") | F19: =IFERROR(VLOOKUP(F18,'Свята'!$A$5:$D$60,4,FALSE),"") | G19: =IFERROR(VLOOKUP(G18,'Свята'!$A$5:$D$60,4,FALSE),"")
B20: 🪨 Камінь у руках · 09:00 Світлий чи темний? Обирайте → | C20: =IFERROR(VLOOKUP(C18,'Свята'!$A$5:$E$60,5,FALSE),"") | D20: 🔨 Як це зроблено · 21:00 До і після полірування → | E20: =IFERROR(VLOOKUP(E18,'Свята'!$A$5:$E$60,5,FALSE),"") | F20: 🎁 Річ у ділі · 21:00 Подарунок чоловікові: 3 ідеї до Михайла і Миколая → | G20: 🔥 Вау-масштаб · 11:00 Застиглі навіки: інклюзи в бурштині →
B22: РУБРИКИ | C22: 🪨 Камінь у руках Пн · 09:00 | D22: 🔨 Як це зроблено Ср · 21:00 | E22: 🎁 Річ у ділі Пт · 21:00 | F22: 🔥 Вау-масштаб Нд · 11:00 | G22: Червоним — церковні, державні і професійні свята (вкладка «Свята»)
B24: Натисніть на відео — відкриється його сценарій у вкладці «Сценарії». Звідти «№ ↑» повертає в календар. Переносите відео — змініть дату і тут, і в «Сценаріях». Свята і підказки підтягуються з вкладки «Свята».
B27: Листопад | F27: 2026
B28: Свята і підказки, як їх використати. Відео на листопад — у наступному плані.
B30: ПОНЕДІЛОК | C30: ВІВТОРОК | D30: СЕРЕДА | E30: ЧЕТВЕР | F30: П’ЯТНИЦЯ | G30: СУБОТА | H30: НЕДІЛЯ
H31: 46327
H32: =IFERROR(VLOOKUP(H31,'Свята'!$A$5:$D$60,4,FALSE),"")
H33: =IFERROR(VLOOKUP(H31,'Свята'!$A$5:$E$60,5,FALSE),"")
B34: 46328 | C34: 46329 | D34: 46330 | E34: 46331 | F34: 46332 | G34: 46333 | H34: 46334
B35: =IFERROR(VLOOKUP(B34,'Свята'!$A$5:$D$60,4,FALSE),"") | C35: =IFERROR(VLOOKUP(C34,'Свята'!$A$5:$D$60,4,FALSE),"") | D35: =IFERROR(VLOOKUP(D34,'Свята'!$A$5:$D$60,4,FALSE),"") | E35: =IFERROR(VLOOKUP(E34,'Свята'!$A$5:$D$60,4,FALSE),"") | F35: =IFERROR(VLOOKUP(F34,'Свята'!$A$5:$D$60,4,FALSE),"") | G35: =IFERROR(VLOOKUP(G34,'Свята'!$A$5:$D$60,4,FALSE),"") | H35: =IFERROR(VLOOKUP(H34,'Свята'!$A$5:$D$60,4,FALSE),"")
B36: =IFERROR(VLOOKUP(B34,'Свята'!$A$5:$E$60,5,FALSE),"") | C36: =IFERROR(VLOOKUP(C34,'Свята'!$A$5:$E$60,5,FALSE),"") | D36: =IFERROR(VLOOKUP(D34,'Свята'!$A$5:$E$60,5,FALSE),"") | E36: =IFERROR(VLOOKUP(E34,'Свята'!$A$5:$E$60,5,FALSE),"") | F36: =IFERROR(VLOOKUP(F34,'Свята'!$A$5:$E$60,5,FALSE),"") | G36: =IFERROR(VLOOKUP(G34,'Свята'!$A$5:$E$60,5,FALSE),"") | H36: =IFERROR(VLOOKUP(H34,'Свята'!$A$5:$E$60,5,FALSE),"")
B37: 46335 | C37: 46336 | D37: 46337 | E37: 46338 | F37: 46339 | G37: 46340 | H37: 46341
B38: =IFERROR(VLOOKUP(B37,'Свята'!$A$5:$D$60,4,FALSE),"") | C38: =IFERROR(VLOOKUP(C37,'Свята'!$A$5:$D$60,4,FALSE),"") | D38: =IFERROR(VLOOKUP(D37,'Свята'!$A$5:$D$60,4,FALSE),"") | E38: =IFERROR(VLOOKUP(E37,'Свята'!$A$5:$D$60,4,FALSE),"") | F38: =IFERROR(VLOOKUP(F37,'Свята'!$A$5:$D$60,4,FALSE),"") | G38: =IFERROR(VLOOKUP(G37,'Свята'!$A$5:$D$60,4,FALSE),"") | H38: =IFERROR(VLOOKUP(H37,'Свята'!$A$5:$D$60,4,FALSE),"")
B39: =IFERROR(VLOOKUP(B37,'Свята'!$A$5:$E$60,5,FALSE),"") | C39: =IFERROR(VLOOKUP(C37,'Свята'!$A$5:$E$60,5,FALSE),"") | D39: =IFERROR(VLOOKUP(D37,'Свята'!$A$5:$E$60,5,FALSE),"") | E39: =IFERROR(VLOOKUP(E37,'Свята'!$A$5:$E$60,5,FALSE),"") | F39: =IFERROR(VLOOKUP(F37,'Свята'!$A$5:$E$60,5,FALSE),"") | G39: =IFERROR(VLOOKUP(G37,'Свята'!$A$5:$E$60,5,FALSE),"") | H39: =IFERROR(VLOOKUP(H37,'Свята'!$A$5:$E$60,5,FALSE),"")
B40: 46342 | C40: 46343 | D40: 46344 | E40: 46345 | F40: 46346 | G40: 46347 | H40: 46348
B41: =IFERROR(VLOOKUP(B40,'Свята'!$A$5:$D$60,4,FALSE),"") | C41: =IFERROR(VLOOKUP(C40,'Свята'!$A$5:$D$60,4,FALSE),"") | D41: =IFERROR(VLOOKUP(D40,'Свята'!$A$5:$D$60,4,FALSE),"") | E41: =IFERROR(VLOOKUP(E40,'Свята'!$A$5:$D$60,4,FALSE),"") | F41: =IFERROR(VLOOKUP(F40,'Свята'!$A$5:$D$60,4,FALSE),"") | G41: =IFERROR(VLOOKUP(G40,'Свята'!$A$5:$D$60,4,FALSE),"") | H41: =IFERROR(VLOOKUP(H40,'Свята'!$A$5:$D$60,4,FALSE),"")
B42: =IFERROR(VLOOKUP(B40,'Свята'!$A$5:$E$60,5,FALSE),"") | C42: =IFERROR(VLOOKUP(C40,'Свята'!$A$5:$E$60,5,FALSE),"") | D42: =IFERROR(VLOOKUP(D40,'Свята'!$A$5:$E$60,5,FALSE),"") | E42: =IFERROR(VLOOKUP(E40,'Свята'!$A$5:$E$60,5,FALSE),"") | F42: =IFERROR(VLOOKUP(F40,'Свята'!$A$5:$E$60,5,FALSE),"") | G42: =IFERROR(VLOOKUP(G40,'Свята'!$A$5:$E$60,5,FALSE),"") | H42: =IFERROR(VLOOKUP(H40,'Свята'!$A$5:$E$60,5,FALSE),"")
B43: 46349 | C43: 46350 | D43: 46351 | E43: 46352 | F43: 46353 | G43: 46354 | H43: 46355
B44: =IFERROR(VLOOKUP(B43,'Свята'!$A$5:$D$60,4,FALSE),"") | C44: =IFERROR(VLOOKUP(C43,'Свята'!$A$5:$D$60,4,FALSE),"") | D44: =IFERROR(VLOOKUP(D43,'Свята'!$A$5:$D$60,4,FALSE),"") | E44: =IFERROR(VLOOKUP(E43,'Свята'!$A$5:$D$60,4,FALSE),"") | F44: =IFERROR(VLOOKUP(F43,'Свята'!$A$5:$D$60,4,FALSE),"") | G44: =IFERROR(VLOOKUP(G43,'Свята'!$A$5:$D$60,4,FALSE),"") | H44: =IFERROR(VLOOKUP(H43,'Свята'!$A$5:$D$60,4,FALSE),"")
B45: =IFERROR(VLOOKUP(B43,'Свята'!$A$5:$E$60,5,FALSE),"") | C45: =IFERROR(VLOOKUP(C43,'Свята'!$A$5:$E$60,5,FALSE),"") | D45: =IFERROR(VLOOKUP(D43,'Свята'!$A$5:$E$60,5,FALSE),"") | E45: =IFERROR(VLOOKUP(E43,'Свята'!$A$5:$E$60,5,FALSE),"") | F45: =IFERROR(VLOOKUP(F43,'Свята'!$A$5:$E$60,5,FALSE),"") | G45: =IFERROR(VLOOKUP(G43,'Свята'!$A$5:$E$60,5,FALSE),"") | H45: =IFERROR(VLOOKUP(H43,'Свята'!$A$5:$E$60,5,FALSE),"")
B46: 46356
B47: =IFERROR(VLOOKUP(B46,'Свята'!$A$5:$D$60,4,FALSE),"")
...

Sheet Сценарії
A1: Сценарії TikTok · жовтень 2026
A2: Натисніть «№ ↑», щоб повернутися в календар. Поля [__] заповнює клієнт. Статус обирайте зі списку.
A4: № | B4: Дата | C4: День | D4: Час | E4: Рубрика | F4: Назва відео | G4: Свято / привід | H4: Суть відео | I4: Хук: перші 1–2 с і текст на екрані | J4: Розкадровка | K4: Тривалість | L4: Звук | M4: Опис і хештеги | N4: Закріплений коментар / заклик | O4: Мета: що дасть | P4: KPI-орієнтир | Q4: Референс | R4: Що потрібно для зйомки | S4: Статус | T4: Коментар клієнта
A5: 1 ↑ | B5: 46300 | C5: Пн | D5: 09:00 | E5: 🪨 Камінь у руках | F5: Скільки коштує цей камінь? | G5: =IFERROR(VLOOKUP(B5,'Свята'!$A$5:$D$60,2,FALSE),"") | H5: Рука дістає з контейнера великі шматки сирцю і по черзі підносить до світла. Глядач вгадує ціну в коментарях — так типовий коментар «бачу в руках гроші» стає грою. | I5: Рука занурюється в повний контейнер і виносить до камери найбільший камінь. Текст: «Скільки, по-вашому, коштує цей камінь?» | J5: 0–2 с — контейнер, рука дістає найбільший камінь (хук) 2–8 с — 3 камені по черзі на світлі від вікна, повільний поворот 8–12 с — камінь на вагах, вага на екрані 12–14 с — камінь повертається в контейнер (кадр як на початку → петля) | K5: 12–15 с | L5: Спокійний трек тихо + живий стукіт каміння | M5: Вгадаєте ціну? Відповідь — завтра в коментарях 👇 #ambergalbin #бурштин #сирець #рівне | N5: Пишіть свою ціну! Правильну відповідь закріпимо завтра. Каталог — посилання в профілі | O5: Повторюємо формат «камінь у руках» (27,6 тис.) і додаємо гру: коментарі піднімають ролик у «Для тебе». Збираємо питання про ціну для відео №7. | P5: ≥10 тис. переглядів, ≥30 коментарів | Q5: «З камінням: необроблений бурштин» | R5: Контейнер сирцю, 3 великі камені, ваги, денне світло. Ціна каменю — [__] ₴ (від клієнта) | S5: Ідея
A6: 2 ↑ | B6: 46302 | C6: Ср | D6: 21:00 | E6: 🎁 Річ у ділі | F6: Завтра День юриста: 3 подарунки для кабінету | G6: ⚖️ День юриста — 8.10 | H6: Підбірка напередодні Дня юриста (8.10): три вироби для робочого столу юриста, адвоката чи нотаріуса — з ціною на екрані. Аудиторія з високим доходом і традицією ділових подарунків. Через свято середа цього тижня віддана рубриці «Річ у ділі», а «Як це зроблено» переїжджає на п’ятницю. | I6: Виріб ставиться на дерев’яний стіл поруч із кодексом і печаткою. Текст: «Що подарувати юристу? 3 ідеї» | J6: 0–2 с — хук: стіл кабінету, перший виріб 2–7 с — письмовий набір: ручку виймають з підставки, ціна на екрані 7–12 с — шахи: рука ставить короля на дошку, ціна 12–17 с — настільна статуетка на світлі, ціна 17–20 с — усі три вироби на столі, текст «Замовлення — в Direct» | K6: 18–20 с | L6: Спокійний «діловий» трек + субтитри, без голосу | M6: Подарунок до Дня юриста ⚖️ Ціни — на відео #ambergalbin #деньюриста #подарунокюристу #бурштин | N6: Письмовий набір [__] ₴, шахи [__] ₴, статуетка [__] ₴. Гравіювання — [так/ні]. Замовити — посилання в профілі або Direct | O6: Продаж платоспроможній аудиторії саме тоді, коли подарунок шукають. Перший тест «ділових» подарунків; уроки «Доміно» враховані: старт із дії, ціна одразу. | P6: ≥3 тис. переглядів, перегляди профілю ≥3%, запити в Direct | Q6: «Доміно з бурштину» (помилки, які не повторюємо) | R6: 3 вироби для кабінету з каталогу (обирає клієнт), дерев’яний стіл, кодекс і папки як реквізит, ціни | S6: Ідея
A7: 3 ↑ | B7: 46304 | C7: Пт | D7: 21:00 | E7: 🔨 Як це зроблено | F7: Від сирцю до кулона за 15 секунд | G7: =IFERROR(VLOOKUP(B7,'Свята'!$A$5:$D$60,2,FALSE),"") | H7: Один камінь проходить увесь шлях: сирий шматок → розпил → шліфування → полірування → свердління → готовий кулон. Монтаж у ритм, без пояснень. | I7: Брудний сирий камінь у долоні — різкий перехід на готовий сяючий кулон — «перемотка» назад. Текст: «Цей камінь ми видобули самі» | J7: 0–1 с — сирий камінь → флеш-кадр готового кулона 1–4 с — розпил, пил, руки майстра 4–8 с — шліфування на кругу, камінь світлішає 8–11 с — полірування, перший блиск 11–13 с — свердління / кріплення 13–15 с — кулон у долоні на світлі; текст «Від надр до прикраси — без посередників» | K7: 15 с | L7: Ритмічний трек, монтаж на біт + живі звуки верстатів | M7: Від надр Рівненщини до вашої прикраси 🔥 #ambergalbin #бурштин #ручнаробота #якцезроблено | N7: Хочете побачити, як роблять браслет? Пишіть — знімемо. Кулони — посилання в профілі | O7: Показує головну перевагу бренду: видобувник і виробник в одному, звідси ціни виробника. Будує довіру і підписки. | P7: ≥5 тис. переглядів, ≥15 нових підписників | Q7: «Один день на виробництві» | R7: Один камінь, проведений через усі етапи (1–2 год у майстерні), штатив | S7: Ідея
A8: 4 ↑ | B8: 46306 | C8: Нд | D8: 11:00 | E8: 🔥 Вау-масштаб | F8: Картина з бурштину, ч.2 | G8: =IFERROR(VLOOKUP(B8,'Свята'!$A$5:$D$60,2,FALSE),"") | H8: Продовження рекордного формату. Майстер піднімає зі столу велику картину чи ікону, розвертає до камери, камера наїжджає на деталі. У фіналі — питання, скільки в ній шматочків бурштину. | I8: Майстер береться за край роботи на столі і рвучко піднімає її. Текст: «Ламаємо стереотипи про картини з бурштину🔥 ч.2» | J8: 0–2 с — підйом роботи зі столу (як у референсі) 2–5 с — майстер тримає роботу перед собою, видно масштаб 5–10 с — макро: обличчя/очі, переливи на світлі, повільний рух камери 10–13 с — загальний план; текст «Скільки тут шматочків? 👇» | K8: 12–14 с | L8: Той самий тип треку, що в референсі, без голосу | M8: Картини з українського бурштину 🎨 #ambergalbin #картиназбурштину #бурштин #рівне | N8: Правильна відповідь: [__] шматочків. Індивідуальні замовлення — посилання в профілі | O8: Рекордний формат (152,4 тис., 733 поширення) + гра в коментарях. Серія «ч.2, ч.3» привчає повертатися і підписуватися. | P8: ≥20 тис. переглядів, поширення ≥0,4% | Q8: «Картину з бурштину — ефект вау» | R8: Велика картина/ікона, майстер у кадрі, світла майстерня, геотег Рівне, кількість шматочків від майстра | S8: Ідея
A9: 5 ↑ | B9: 46307 | C9: Пн | D9: 09:00 | E9: 🪨 Камінь у руках | F9: ASMR: звук бурштину | G9: =IFERROR(VLOOKUP(B9,'Свята'!$A$5:$D$60,2,FALSE),"") | H9: Сирий бурштин пересипається з долонь у скляну миску. Без тексту і музики — лише звук. Кадр зациклюється. | I9: Жменя каменів падає в миску крупним планом зі звуком. Без тексту. | J9: 0–4 с — пересипання з долонь, крупно, мікрофон близько 4–9 с — пальці перебирають камені, світло крізь них 9–12 с — нова жменя (той самий рух, що на початку) → петля | K9: 10–12 с | L9: Лише живий звук: тихе приміщення, мікрофон біля миски | M9: Звук бурштину 🎧 #ambergalbin #asmr #бурштин #сирець | N9: Ще більше процесів — у профілі | O9: Повторюємо ASMR-лідера (12,2 тис., 71% утримання, понад половина нових підписників тижня). Висока досмотрюваність штовхає ролик у «Для тебе». | P9: ≥8 тис. переглядів, середній час ≥70% | Q9: ASMR 25.09 + «З камінням: необроблений бурштин» | R9: Сирець дрібної/середньої фракції, скляна миска, тиша, петличка | S9: Ідея
A10: 6 ↑ | B10: 46309 | C10: Ср | D10: 21:00 | E10: 🔨 Як це зроблено | F10: Як ми робимо статуетку військової техніки | G10: =IFERROR(VLOOKUP(B10,'Свята'!$A$5:$D$60,2,FALSE),"") | H10: Швидкими кадрами — створення статуетки (танк, літак чи корабель): від підбору каменів до готової фігури на підставці. | I10: Готова статуетка на 1 секунду, потім «перемотка» назад до купки каменів. Текст: «Як з цих каменів виходить…» | J10: 0–1 с — готова фігура → перемотка 1–4 с — підбір каменів за кольором 4–9 с — обробка деталей, збирання (крупно руки) 9–12 с — полірування 12–15 с — фігура на підставці, наїзд | K10: 15 с | L10: Ритмічний трек, монтаж на біт | M10: Подарунок тим, хто служить 🇺🇦 #ambergalbin #статуетка #ручнаробота #бурштин | N10: Статуетки «Військова техніка» — у каталозі, посилання в профілі | O10: Довіра через процес + тема, близька чоловічій аудиторії (64%). Категорія «Військова техніка» — подарунок військовим. | P10: ≥5 тис. переглядів, ≥15 нових підписників | Q10: «Один день на виробництві» | R10: Процес виготовлення статуетки (2–3 етапи), ціна | S10: Ідея
A11: 7 ↑ | B11: 46311 | C11: Пт | D11: 21:00 | E11: 🎁 Річ у ділі | F11: Відповідаю: скільки коштує бурштин? | G11: =IFERROR(VLOOKUP(B11,'Свята'!$A$5:$D$60,2,FALSE),"") | H11: Відповідь на реальний коментар («боюся навіть питатись, скільки це…» або «Яка вартість…»). Три вироби від доступного до преміум з ціною на екрані. Закриваємо найчастіше питання і пошуковий запит. | I11: Картка коментаря на екрані. Текст: «Відповідаю чесно 👇» | J11: 0–2 с — картка коментаря (функція «Відповісти відео») 2–6 с — кулон у долоні, ціна на екрані (від 150 ₴) 6–10 с — браслет на зап’ясті, ціна (від 800 ₴) 10–15 с — картина: «від [__] ₴ або під замовлення» 15–18 с — «Ціна залежить від: розміру · прозорості · обробки» | K11: 18–22 с | L11: Голос майстра або консультанта + субтитри; фраза «скільки коштує бурштин» звучить уголос | M11: Скільки коштує бурштин? Від 150 ₴ до … #ambergalbin #скількикоштуєбурштин #бурштин #прикраси | N11: Каталог із цінами — посилання в профілі. Питайте ціну будь-якого виробу тут 👇 | O11: Знімаємо ціновий бар’єр: під кожним референсом питають ціну. Ловимо пошуковий трафік і ведемо в каталог. | P11: ≥4 тис. переглядів, перегляди профілю ≥4% | Q11: Коментарі під «Картину з бурштину — ефект вау» і «З камінням: необроблений бурштин» | R11: 3 вироби, актуальні ціни від клієнта, реальний коментар для відповіді. Ціни 150/800 ₴ — з сайту, перевірити | S11: Ідея
A12: 8 ↑ | B12: 46313 | C12: Нд | D12: 11:00 | E12: 🔥 Вау-масштаб | F12: День апостола Луки: ікона з бурштину | G12: ⛪ Апостола Луки — 18.10 | H12: За переданням апостол Лука написав першу ікону Богородиці — тому він покровитель іконописців. У його день показуємо велику ікону з бурштину: майстер піднімає її зі столу, камера наближається до лику і переливів на світлі. | I12: Майстер обережно піднімає зі столу велику ікону, світло з вікна запалює бурштин. Текст: «Ікона, складена з бурштину» | J12: 0–2 с — підйом ікони зі столу (як в «Орлі») 2–5 с — майстер тримає ікону перед собою, видно масштаб 5–10 с — макро: лик, німб, переливи на світлі, повільний рух камери 10–13 с — ікона на підставці, текст «18.10 — день апостола Луки, покровителя іконописців» | K12: 12–14 с | L12: Тиха хорова або інструментальна музика, без голосу | M12: Сьогодні день апостола Луки — покровителя іконописців 🙏 Ікона з українського бурштину #ambergalbin #іконазбурштину #бурштин #рівне | N12: Ікони під замовлення, зокрема іменні, — від [__] ₴, виготовлення [__] днів. Деталі — в Direct | O12: Вау-формат рекорду («Орел», 152,4 тис.) на найдорожчій категорії — іконах — у церковний привід. Готує ґрунт для іменних ікон (№11) і подарункового сезону. | P12: ≥15 тис. переглядів, збереження ≥1%, поширення ≥0,4% | Q12: «Картину з бурштину — ефект вау» | R12: Велика ікона з бурштину, майстер у кадрі, денне світло. Ціни і терміни — від клієнта. Тон шанобливий, без жартів | S12: Ідея
A13: 9 ↑ | B13: 46314 | C13: Пн | D13: 09:00 | E13: 🪨 Камінь у руках | F13: Справжній чи підробка? Тест солоною водою | G13: =IFERROR(VLOOKUP(B13,'Свята'!$A$5:$D$60,2,FALSE),"") | H13: Простий домашній тест: у насиченому розчині солі справжній бурштин спливає, а скло і більшість пластиків тонуть. Порівнюємо справжню намистину зі скляною підробкою. Чесно кажемо, що це перший фільтр, а не гарантія: копал і деякі пластики теж спливають. | I13: Дві схожі намистини над склянкою. Текст: «Одна з них — підробка. Яка?» | J13: 0–2 с — хук 2–5 с — сіль сиплеться у воду, розмішування (прискорено) 5–9 с — кидаємо обидві: одна спливає, інша тоне 9–12 с — текст «Бурштин спливає, скло тоне», намистина в долоні 12–14 с — текст «Це перший фільтр. 100% — лише експертиза» | K13: 13 с | L13: Трек з паузою-інтригою + звук «бульк» | M13: Як перевірити бурштин удома 🔍 #ambergalbin #якперевіритибурштин #справжнійбурштин #бурштин | N13: Важливо: тест відсіює скло і більшість пластиків, але не копал. Ще способи перевірки? Пишіть «+» — знімемо частину 2 | O13: Корисне відео: збереження і поширення, пошуковий трафік надовго, експертність виробника. | P13: ≥10 тис. переглядів, збереження ≥1,5% | Q13: «З камінням: необроблений бурштин» | R13: Справжня намистина + скляна підробка (не пластик: деякі пластики спливають), сіль, прозора склянка. Формулювання погодити з майстром | S13: Ідея
A14: 10 ↑ | B14: 46316 | C14: Ср | D14: 21:00 | E14: 🔨 Як це зроблено | F14: Один день на виробництві за 20 секунд | G14: =IFERROR(VLOOKUP(B14,'Свята'!$A$5:$D$60,2,FALSE),"") | H14: Таймкоди дня: від відкриття до відправки замовлення. Швидкі кадри, живий звук, обличчя команди. | I14: Відчиняються двері майстерні, вмикається світло. Текст: «Один день на виробництві бурштину» | J14: 0–2 с — 08:00 відкриття, світло 2–6 с — 09:00 сортування сирцю 6–11 с — 11:00 майстри за верстатами (3 короткі кадри) 11–15 с — 14:00 полірування, збирання прикрас 15–19 с — 17:00 пакування замовлення, коробка з лого 19–20 с — майстер махає в камеру / вимикає світло | K14: 18–22 с | L14: Трек із ритмом + живі звуки; таймкоди на екрані | M14: Так виглядає наш день 🛠 #ambergalbin #виробництво #деньмайстра #бурштин | N14: Про що зняти наступне відео? Пишіть 👇 | O14: Обличчя бренду і довіра (видобувник → виробник → магазин), ріст підписок. Тест довшого формату — гіпотеза з чернетки. | P14: ≥5 тис. переглядів, ≥15 нових підписників | Q14: «Один день на виробництві» | R14: Знімальний день у майстерні, згода команди на зйомку | S14: Ідея
A15: 11 ↑ | B15: 46318 | C15: Пт | D15: 21:00 | E15: 🎁 Річ у ділі | F15: День ангела Дмитра: іменна ікона в подарунок | G15: ⛪ Св. Димитрія, іменини — 26.10 | H15: 26.10 — день великомученика Димитрія Солунського, іменини Дмитрів. Показуємо іменну ікону святого Димитрія з бурштину як подарунок на іменини — з ціною і терміном. Відео відкриває серію іменинних подарунків: далі Михайло (8.11), Катерина (24.11), Андрій (30.11), Варвара (4.12), Миколай (6.12), Анна (9.12). | I15: Руки кладуть іменну ікону в подарункову коробку. Текст: «Є знайомий Дмитро? У понеділок — його іменини» | J15: 0–2 с — хук: ікона в долонях над коробкою 2–7 с — ікона на світлі, макро лику й обладунків святого-воїна 7–11 с — ікона в коробці, стрічка, ціна на екрані 11–14 с — текст «Іменні ікони: Михайло, Андрій, Миколай — наступні» | K15: 13–15 с | L15: Спокійний трек без голосу; субтитри | M15: 26 жовтня — День ангела Дмитра 🙏 Іменна ікона з бурштину #ambergalbin #деньангела #іменнаікона #бурштин | N15: Іменна ікона — від [__] ₴, виготовлення [__] днів. Напишіть ім’я — підкажемо, чи встигнемо до іменин | O15: Продаж найдорожчої категорії в церковний привід і старт серії іменинних подарунків на листопад–грудень. Привчаємо замовляти заздалегідь. | P15: ≥3 тис. переглядів, перегляди профілю ≥3%, запити в Direct | Q15: «Доміно з бурштину» (ціна одразу) + «Картину з бурштину — ефект вау» (макро на світлі) | R15: Іменна ікона св. Димитрія (у наявності або зразок), подарункова упаковка, ціни і терміни від клієнта | S15: Ідея
A16: 12 ↑ | B16: 46320 | C16: Нд | D16: 11:00 | E16: 🔥 Вау-масштаб | F16: Шахи з бурштину: розставляємо партію | G16: =IFERROR(VLOOKUP(B16,'Свята'!$A$5:$D$60,2,FALSE),"") | H16: Сатисфайінг-розстановка: руки швидко ставлять фігури на дошку, кожна — в біт. Фінал — повна дошка зверху і король крупно на світлі. | I16: Король із бурштину ставиться в центр кадру з гучним «тук». Текст: «Шахи, які не соромно поставити в кабінеті» | J16: 0–1 с — король на дошці крупно 1–8 с — прискорена розстановка, кожна фігура в біт 8–12 с — макро фігур на світлі (ферзь, кінь) 12–15 с — кадр зверху: повна дошка, лого | K16: 15 с | L16: Ритмічний трек, «тук» кожної фігури в біт | M16: Партія в бурштині ♟️ #ambergalbin #шахи #бурштин #подарунокчоловікові | N16: Ціна — [__] ₴. Нарди й доміно теж є — посилання в профілі | O16: Охоплення + чоловіча аудиторія; підготовка до подарункового сезону (Михайло 8.11, Миколай 6.12). 24.10 — Дмитрівська поминальна субота, тож у суботу нічого не публікуємо. | P16: ≥10 тис. переглядів, збереження ≥1% | Q16: «Картину з бурштину — ефект вау» (масштаб, деталі) | R16: Шахи, дошка, штатив зверху, ціна | S16: Ідея
A17: 13 ↑ | B17: 46321 | C17: Пн | D17: 09:00 | E17: 🪨 Камінь у руках | F17: Світлий чи темний? Обирайте | G17: =IFERROR(VLOOKUP(B17,'Свята'!$A$5:$D$60,2,FALSE),"") | H17: Руки сортують сирець на дві купки — світлий і темний. Глядач обирає свій колір одним словом у коментарях. | I17: Два камені — світлий і темний — у двох долонях перед камерою. Текст: «Світлий чи темний? Обирайте 👇» | J17: 0–2 с — дві долоні, два камені 2–8 с — швидке сортування на дві купки під біт 8–11 с — обидві купки на світлі, крупно 11–12 с — знову дві долоні → петля | K17: 12 с | L17: Ритмічний трек, стук каміння в біт | M17: Команда світлого чи темного? #ambergalbin #бурштин #сирець #рівне | N17: Прикраси обох кольорів — посилання в профілі | O17: Легкий вхід у коментарі (одне слово) → активність і охоплення. Дізнаємось, який колір цікавіший, для майбутніх добірок. | P17: ≥8 тис. переглядів, ≥40 коментарів | Q17: «З камінням: необроблений бурштин» | R17: Сирець різного кольору, світлий фон | S17: Ідея
A18: 14 ↑ | B18: 46323 | C18: Ср | D18: 21:00 | E18: 🔨 Як це зроблено | F18: До і після полірування | G18: =IFERROR(VLOOKUP(B18,'Свята'!$A$5:$D$60,2,FALSE),"") | H18: Один камінь у двох станах: матовий сирець → змах руки → уже блищить. 2–3 такі пари на різних виробах, потім процес полірування. | I18: Матовий камінь, схожий на звичайну гальку. Текст: «Виглядає як звичайна галька…» | J18: 0–2 с — матовий камінь крупно 2–3 с — змах руки → перехід на полірований 3–9 с — ще 2 пари «до/після» (намистина, кулон) 9–13 с — полірування на кругу, відблиски 13–15 с — готові вироби поруч | K18: 15 с | L18: Трек із «дропом» на моменті переходу | M18: Різниця, яку робить майстер ✨ #ambergalbin #доіпісля #бурштин #ручнаробота | N18: Поліровані й шліфовані вироби — в каталозі | O18: Вау-трансформація тримає увагу до кінця і пояснює цінність ручної роботи. Тема нейтральна для пам’ятного дня 28.10. | P18: ≥6 тис. переглядів, середній час ≥60% | Q18: «Один день на виробництві» | R18: 3 пари «сирець / готовий виріб», поліровальний круг | S18: Ідея
A19: 15 ↑ | B19: 46325 | C19: Пт | D19: 21:00 | E19: 🎁 Річ у ділі | F19: Подарунок чоловікові: 3 ідеї до Михайла і Миколая | G19: ⛪ Михайла 8.11 · 🎁 Миколая 6.12 — анонс | H19: Старт подарункового сезону: 8.11 — іменини Михайлів, 6.12 — Миколая. Три вироби для чоловіка з цінами: нарди, доміно, статуетка. Доміно повертається в план у форматі живої гри. | I19: Руки ставлять перший виріб на стіл. Текст: «Не знаєте, що подарувати чоловікові?» | J19: 0–2 с — хук, перший виріб 2–7 с — нарди: відкриття, кидок кубиків, ціна 7–12 с — доміно: кісточки з гуркотом висипаються на стіл, ціна 12–17 с — статуетка на світлі, ціна 17–20 с — усі три разом, текст «Доставка по Україні» | K19: 18–20 с | L19: Голос або текст + легкий трек; субтитри | M19: Подарунок, який запам’ятається 🎁 #ambergalbin #подарунокчоловікові #ідеяподарунка #бурштин | N19: Ціни: нарди [__] ₴, доміно [__] ₴, статуетка [__] ₴. Замовити до Михайла — до [__] (термін від клієнта) | O19: Прямі продажі чоловічій аудиторії (64%) і старт подарункового сезону на місяць раніше. | P19: ≥4 тис. переглядів, перегляди профілю ≥4% | Q19: «Доміно з бурштину» + чернетка v2 (подарунок чоловікові) | R19: 3 вироби, ціни, нейтральний стіл | S19: Ідея
A20: 16 ↑ | B20: 46326 | C20: Сб | D20: 11:00 | E20: 🔥 Вау-масштаб | F20: Застиглі навіки: інклюзи в бурштині | G20: =IFERROR(VLOOKUP(B20,'Свята'!$A$5:$D$60,2,FALSE),"") | H20: Макро найефектніших інклюзів (комахи, павуки, рослини) у темряві з ліхтариком. Закриваємо місяць вау-форматом. Таємнича подача працює без прив’язки до Хелловіну. | I20: Темрява, за каменем вмикається ліхтарик — проступає силует комахи. Текст: «Вони застигли тут задовго до людей…» | J20: 0–2 с — хук у темряві 2–8 с — 3 інклюзи по черзі, макро з ліхтариком 8–11 с — найкращий, повільний наїзд 11–13 с — світло вмикається, камінь у долоні, текст «Їм десятки мільйонів років» | K20: 13 с | L20: Таємничий трек | M20: Мешканці бурштину, яким десятки мільйонів років 🕷 #ambergalbin #інклюз #бурштин #рівне | N20: Камені з інклюзом — у розділі «Камінь» на сайті | O20: Охоплення на унікальному товарі (камінь з інклюзом). Вау-ефект без великих витрат. | P20: ≥15 тис. переглядів, збереження ≥1% | Q20: «Картину з бурштину — ефект вау» (макро) + «З камінням: необроблений бурштин» | R20: 3–4 камені з інклюзом, ліхтарик, макролінза, темне приміщення | S20: Ідея

Sheet Рубрики
A1: Рубрики і правила
A2: На чому базується план: 3 референси з папки referens (статистика знята з екранних записів), звіт TikTok 22–28.09 з чернетки v2 (84,5% трафіку — «Для тебе», 5,9% — пошук; 64% підписників — чоловіки; найкраще відео вийшло о 9:12, пік активності підписників — близько опівночі) та каталог ambergalbin.store.
B4: Рубрика | C4: Слот | D4: Суть | E4: Референс і цифри | F4: Мета: що дає | G4: Інші KPI | H4: Ціль переглядів
A5: 1 | B5: 🪨 Камінь у руках | C5: Пн · 09:00 | D5: Сирий бурштин крупно в руках і на світлі: сенсорика, живий звук, гра з глядачем (вгадай ціну, обери колір, перевір справжність). | E5: «З камінням: необроблений бурштин» — 27,6 тис. переглядів, 86 поширень; ASMR 25.09 — 12,2 тис., 71% утримання (звіт 22–28.09). | F5: Охоплення через «Для тебе» (84,5% трафіку), високе утримання, коментарі. Ранковий слот — найкраще відео вийшло о 9:12. | G5: Середній час перегляду ≥60%, коментарі ≥30 | H5: 10000
A6: 2 | B6: 🔨 Як це зроблено | C6: Ср · 21:00 | D6: Швидкі кадри виробництва: від сирцю до готового виробу, руки майстрів, верстати, живий звук. Монтаж у ритм. | E6: «Один день на виробництві — швидкі кадри» + висновок звіту: нативні процеси без постановки — стабільно добрий формат. | F6: Довіра: бренд — видобувник і виробник, звідси ціни виробника. Ріст підписок, довгий хвіст переглядів. | G6: Нові підписники ≥15 з відео | H6: 5000
A7: 3 | B7: 🎁 Річ у ділі | C7: Пт · 21:00 | D7: Виріб у дії (грають, носять, перебирають) + ціна на екрані або в закріпленому коментарі. Сюди ж — відео-відповіді на коментарі про ціну. | E7: «Доміно з бурштину» — 2,7 тис., але ER 3,8% і питання «Можна ціну?». Слабкий хук (закрита коробка) і немає ціни — виправляємо. | F7: Продажі: перегляди профілю, переходи на сайт, звернення в Direct. Чоловіча аудиторія — 64% підписників. | G7: Перегляди профілю ≥3% від переглядів, запити ціни | H7: 3000
A8: 4 | B8: 🔥 Вау-масштаб | C8: Нд · 11:00 | D8: Великий або несподіваний виріб: майстер піднімає/розкриває його в кадрі, макро деталей на світлі. Серія «Ламаємо стереотипи». | E8: «Картину з бурштину — ефект вау» — 152,4 тис. переглядів, 9 083 вподобання, 512 збережень, 733 поширення. Рекорд акаунту. | F8: Віральне охоплення, поширення і збереження, впізнаваність бренду. Вихідний денний слот — тест. | G8: Поширення ≥0,4% від переглядів | H8: 20000
B10: Правила для всіх відео
A11: 1 | B11: Вертикаль 9:16, знімаємо нативно на телефон — без «рекламного» лиску (див. «Доміно»).
A12: 2 | B12: Перші 1–2 секунди — дія, звук або питання. Жодних заставок і логотипів на старті.
A13: 3 | B13: Текст на екрані — до 7 слів, у безпечній зоні (не під кнопками і підписом TikTok).
A14: 4 | B14: Ціна — на екрані або в закріпленому коментарі: під кожним референсом питають ціну.
A15: 5 | B15: Перша година після публікації — відповідаємо на всі коментарі; найкращі питання стають відео-відповідями.
A16: 6 | B16: 3–5 хештегів: #ambergalbin + 1–2 тематичні + 1–2 пошукові. Геотег «Рівне» — на кожному відео.
A17: 7 | B17: Зациклення: останній кадр повторює перший — це дає повторні перегляди.
A18: 8 | B18: Через 24–48 год вносимо цифри у вкладку «Заміри». Щоп’ятниці вирішуємо, що повторюємо, а що змінюємо.
A19: 9 | B19: Факти (вік бурштину, тести, ціни, кількість шматочків) підтверджуємо з майстром до публікації. Поля [__] заповнює клієнт.

Sheet Свята
A1: Свята жовтень–грудень 2026
A2: Критерій: церковні свята (за новим календарем ПЦУ та УГКЦ), загальнодержавні дати і професійні дні платоспроможних професій — юристи, прокурори, адвокати, аграрний бізнес, енергетики, дипломати. Пам’ятні дати — без продажних акцентів. Дати перевірені на 2026 рік. Календар бере коротку назву з колонки D за датою: додайте рядок — і свято з’явиться в календарі (одна дата — один рядок).
A4: Дата | B4: Свято / подія | C4: Тип | D4: Коротко для календаря | E4: Як використати в контенті | F4: Відео в плані
A5: 46296 | B5: 🇺🇦 Покрова Пресвятої Богородиці · День захисників і захисниць України | C5: Церковне · Державне | D5: 🇺🇦 Покрова · День захисників | E5: Минуло до старту плану (05.10). Наступного року: ікони Богородиці, подяка захисникам — без прямого продажу. | F5: —
A6: 46301 | B6: ⛪ Апостола Фоми | C6: Церковне | D6: ⛪ Ап. Фоми | E6: Мале свято, іменини Фом: згадка в описі, окремого відео не потрібно. | F6: —
A7: 46303 | B7: ⚖️ День юриста | C7: Професійне · високий чек | D7: ⚖️ День юриста | E7: Юристи, адвокати, нотаріуси, судді: ділові подарунки для кабінету. Підбірку публікуємо напередодні, 07.10. | F7: №2
A8: 46304 | B8: ⛪ Апостола Якова Алфеєвого | C8: Церковне | D8: ⛪ Ап. Якова | E8: Мале свято, іменини Яковів: згадка в описі. | F8: —
A9: 46313 | B9: ⛪ Апостола і євангеліста Луки | C9: Церковне | D9: ⛪ Ап. Луки | E9: За переданням Лука написав першу ікону Богородиці — покровитель іконописців. Показуємо ікону з бурштину. | F9: №8
A10: 46319 | B10: 🕯 Дмитрівська поминальна субота | C10: Церковне · поминальне | D10: 🕯 Дмитрівська субота | E10: Поминальний день: не публікуємо продажного контенту. | F10: —
A11: 46321 | B11: ⛪ Великомученика Димитрія Солунського | C11: Церковне | D11: ⛪ Св. Димитрія · іменини | E11: Іменини Дмитрів: іменна ікона як подарунок. Відео — у п’ятницю 23.10, щоб встигли замовити. | F11: №11
A12: 46323 | B12: 🕯 День вигнання нацистських загарбників з України | C12: Пам’ятне · без продажів | D12: 🕯 Пам’ятний день | E12: Без розважальних і продажних акцентів. Відео №14 нейтральне; за потреби перенести на 29.10. | F12: №14
A13: 46334 | B13: ⛪ Собор архистратига Михаїла | C13: Церковне | D13: ⛪ Михайла · іменини | E13: Іменини Михайлів; архистратиг — покровитель Києва. Іменна ікона чи подарунок Михайлу — за 3–5 днів до свята. | F13: Листопад; анонс у №11, №15
A14: 46335 | B14: 🇺🇦 День української писемності та мови | C14: Державне | D14: 🇺🇦 День писемності | E14: Письмові набори і ручки з бурштину, українське слово в текстах на екрані. | F14: Листопад
A15: 46341 | B15: 🌾 День працівників сільського господарства · початок Різдвяного посту | C15: Професійне · високий чек · Церковне | D15: 🌾 День аграрія · піст | E15: Власники і керівники агробізнесу — платоспроможна аудиторія регіону: подарунки для кабінету, статуетки. З 15.11 до 24.12 — Різдвяний піст: тон стриманіший. | F15: Листопад
A16: 46347 | B16: ⛪ Введення в храм Пресвятої Богородиці · 🇺🇦 День Гідності та Свободи | C16: Церковне · Державне | D16: ⛪ Введення · День Гідності | E16: Ікони Богородиці. Державна дата — урочисто, без продажних акцентів. | F16: Листопад
... A28: 46387 | B28: 🎆 Щедрий вечір (свята Меланії) · Новий рік | C28: Церковне · Державне | D28: 🎆 Меланки · Новий рік | E28: Новорічні подарунки, підсумки року бренду. | F28: Грудень

Sheet Референси
A1: Референси: що спрацювало і чому
A2: Цифри зняті з екранних записів TikTok у папці referens (округлені, як показує TikTok). ER = (вподобання + коментарі + збереження + поширення) / перегляди.
A4: Відео | B4: Опубліковано | C4: Перегляди | D4: Вподобання | E4: Коментарі | F4: Збереження | G4: Поширення | H4: ER | I4: Поширення / перегляди | J4: Що в кадрі | K4: Чому спрацювало / ні | L4: Що беремо в план | M4: Рубрика
A5: «Картину з бурштину — ефект вау» | B5: 46134 | C5: 152400 | D5: 9083 | E5: 230 | F5: 512 | G5: 733 | H5: =IF(AND(C5>0,COUNT(D5:G5)=4),(D5+E5+F5+G5)/C5,"") | I5: =IF(AND(C5>0,G5<>""),G5/C5,"") | J5: Майстер піднімає зі столу велику мозаїку «Орел», розвертає до камери, камера наїжджає на очі й фактуру. Текст «Ламаємо стереотипи про картини з бурштину🔥», геотег Рівне, трек. | K5: Масштаб + несподіванка (бурштин — не лише прикраси), людина в кадрі для розміру, деталі на світлі, текст-виклик. Коментарі — про ціну («боюся навіть питатись, скільки це…»). | L5: Серія «Ламаємо стереотипи» ч.2/ч.3, великі роботи + макро, відповідь про ціну окремим відео. | M5: 🔥 Вау-масштаб
A6: «З камінням: необроблений бурштин» | B6: 46017 | C6: 27600 | D6: 613 | E6: 12 | F6: 22 | G6: 86 | H6: =IF(AND(C6>0,COUNT(D6:G6)=4),(D6+E6+F6+G6)/C6,"") | I6: =IF(AND(C6>0,G6<>""),G6/C6,"") | J6: Рука по одному дістає з контейнера великі шматки сирцю і крутить їх на світлі. Трендовий трек, в описі — адреса магазину. | K6: Сирий камінь читається як «скарб у руках»: «я бачу, що в руках гроші». Питають ціну і доставку за кордон. | L6: Рубрика «Камінь у руках»: сирець крупно + гра «вгадай ціну». Окремо відповісти про доставку за кордон. | M6: 🪨 Камінь у руках
A7: «Доміно з бурштину» | B7: 46055 | C7: 2657 | D7: 70 | E7: 6 | F7: 15 | G7: 11 | H7: =IF(AND(C7>0,COUNT(D7:G7)=4),(D7+E7+F7+G7)/C7,"") | I7: =IF(AND(C7>0,G7<>""),G7/C7,"") | J7: Закрита скринька → відкриття → кісточки висипаються → складання назад. Текст «Доміно з бурштину» + лого, фінальна заставка з лого. | K7: Статичний старт (закрита коробка) — слабкий хук; виглядає як реклама; ціни немає — питають «Можна ціну?». При цьому ER 3,8% — товар цікавий. | L7: Рубрика «Річ у ділі»: старт із дії і звуку, виріб у використанні, ціна в закріпі. | M7: 🎁 Річ у ділі
A8: «Один день на виробництві — швидкі кадри» | H8: =IF(AND(C8>0,COUNT(D8:G8)=4),(D8+E8+F8+G8)/C8,"") | I8: =IF(AND(C8>0,G8<>""),G8/C8,"") | J8: Файл більше 10 МБ: коннектор Google Drive такі не віддає, переглянути не вдалося. Ідея — за назвою: швидкий монтаж дня на виробництві. | K8: — | L8: Рубрика «Як це зроблено». Статистику можна дописати вручну в цей рядок. | M8: 🔨 Як це зроблено
A9: ASMR: шліфування (зі звіту 22–28.09) | B9: 46290 | C9: 12200 | H9: =IF(AND(C9>0,COUNT(D9:G9)=4),(D9+E9+F9+G9)/C9,"") | I9: =IF(AND(C9>0,G9<>""),G9/C9,"") | J9: Крупний план обробки каменю, без тексту і голосу, живий звук. | K9: 71% середнього часу перегляду, 32,7% до кінця, 12 нових підписників — понад половина приросту тижня. | L9: ASMR-випуски в рубриці «Камінь у руках» (№5). | M9: 🪨 Камінь у руках

Sheet Заміри
A1: Заміри після публікації
A2: Заповнюємо через 24–48 год з TikTok Studio (білі клітинки). Сірі — рахуються самі. Порівнюйте з референсами: «Орел» — ER 6,9%, «Сирець» — 2,7%, «Доміно» — 3,8%.
A4: № | B4: Дата | C4: Відео | D4: Рубрика | E4: Перегляди | F4: Сер. час перегляду, % | G4: До кінця, % | H4: Вподобання | I4: Коментарі | J4: Збереження | K4: Поширення | L4: Нові підписники | M4: Перегляди профілю | N4: ER | O4: Поширення / перегляди | P4: Ціль переглядів | Q4: Ціль виконано? | R4: Висновок: повторюємо / змінюємо
A5: 1 | B5: ='Сценарії'!B5 | C5: ='Сценарії'!F5 | D5: ='Сценарії'!E5 | N5: =IF(E5>0,(H5+I5+J5+K5)/E5,"") | O5: =IF(E5>0,K5/E5,"") | P5: =IFERROR(VLOOKUP(D5,'Рубрики'!$B$5:$H$8,7,FALSE),"") | Q5: =IF(E5="","",IF(E5>=P5,"✅ так","❌ ні"))
A6: 2 | B6: ='Сценарії'!B6 | C6: ='Сценарії'!F6 | D6: ='Сценарії'!E6 | N6: =IF(E6>0,(H6+I6+J6+K6)/E6,"") | O6: =IF(E6>0,K6/E6,"") | P6: =IFERROR(VLOOKUP(D6,'Рубрики'!$B$5:$H$8,7,FALSE),"") | Q6: =IF(E6="","",IF(E6>=P6,"✅ так","❌ ні"))
A7: 3 | B7: ='Сценарії'!B7 | C7: ='Сценарії'!F7 | D7: ='Сценарії'!E7 | N7: =IF(E7>0,(H7+I7+J7+K7)/E7,"") | O7: =IF(E7>0,K7/E7,"") | P7: =IFERROR(VLOOKUP(D7,'Рубрики'!$B$5:$H$8,7,FALSE),"") | Q7: =IF(E7="","",IF(E7>=P7,"✅ так","❌ ні"))
A8: 4 | B8: ='Сценарії'!B8 | C8: ='Сценарії'!F8 | D8: ='Сценарії'!E8 | N8: =IF(E8>0,(H8+I8+J8+K8)/E8,"") | O8: =IF(E8>0,K8/E8,"") | P8: =IFERROR(VLOOKUP(D8,'Рубрики'!$B$5:$H$8,7,FALSE),"") | Q8: =IF(E8="","",IF(E8>=P8,"✅ так","❌ ні"))
A9: 5 | B9: ='Сценарії'!B9 | C9: ='Сценарії'!F9 | D9: ='Сценарії'!E9 | N9: =IF(E9>0,(H9+I9+J9+K9)/E9,"") | O9: =IF(E9>0,K9/E9,"") | P9: =IFERROR(VLOOKUP(D9,'Рубрики'!$B$5:$H$8,7,FALSE),"") | Q9: =IF(E9="","",IF(E9>=P9,"✅ так","❌ ні"))
A10: 6 | B10: ='Сценарії'!B10 | C10: ='Сценарії'!F10 | D10: ='Сценарії'!E10 | N10: =IF(E10>0,(H10+I10+J10+K10)/E10,"") | O10: =IF(E10>0,K10/E10,"") | P10: =IFERROR(VLOOKUP(D10,'Рубрики'!$B$5:$H$8,7,FALSE),"") | Q10: =IF(E10="","",IF(E10>=P10,"✅ так","❌ ні"))
A11: 7 | B11: ='Сценарії'!B11 | C11: ='Сценарії'!F11 | D11: ='Сценарії'!E11 | N11: =IF(E11>0,(H11+I11+J11+K11)/E11,"") | O11: =IF(E11>0,K11/E11,"") | P11: =IFERROR(VLOOKUP(D11,'Рубрики'!$B$5:$H$8,7,FALSE),"") | Q11: =IF(E11="","",IF(E11>=P11,"✅ так","❌ ні"))
A12: 8 | B12: ='Сценарії'!B12 | C12: ='Сценарії'!F12 | D12: ='Сценарії'!E12 | N12: =IF(E12>0,(H12+I12+J12+K12)/E12,"") | O12: =IF(E12>0,K12/E12,"") | P12: =IFERROR(VLOOKUP(D12,'Рубрики'!$B$5:$H$8,7,FALSE),"") | Q12: =IF(E12="","",IF(E12>=P12,"✅ так","❌ ні"))
A13: 9 | B13: ='Сценарії'!B13 | C13: ='Сценарії'!F13 | D13: ='Сценарії'!E13 | N13: =IF(E13>0,(H13+I13+J13+K13)/E13,"") | O13: =IF(E13>0,K13/E13,"") | P13: =IFERROR(VLOOKUP(D13,'Рубрики'!$B$5:$H$8,7,FALSE),"") | Q13: =IF(E13="","",IF(E13>=P13,"✅ так","❌ ні"))
A14: 10 | B14: ='Сценарії'!B14 | C14: ='Сценарії'!F14 | D14: ='Сценарії'!E14 | N14: =IF(E14>0,(H14+I14+J14+K14)/E14,"") | O14: =IF(E14>0,K14/E14,"") | P14: =IFERROR(VLOOKUP(D14,'Рубрики'!$B$5:$H$8,7,FALSE),"") | Q14: =IF(E14="","",IF(E14>=P14,"✅ так","❌ ні"))
A15: 11 | B15: ='Сценарії'!B15 | C15: ='Сценарії'!F15 | D15: ='Сценарії'!E15 | N15: =IF(E15>0,(H15+I15+J15+K15)/E15,"") | O15: =IF(E15>0,K15/E15,"") | P15: =IFERROR(VLOOKUP(D15,'Рубрики'!$B$5:$H$8,7,FALSE),"") | Q15: =IF(E15="","",IF(E15>=P15,"✅ так","❌ ні"))
A16: 12 | B16: ='Сценарії'!B16 | C16: ='Сценарії'!F16 | D16: ='Сценарії'!E16 | N16: =IF(E16>0,(H16+I16+J16+K16)/E16,"") | O16: =IF(E16>0,K16/E16,"") | P16: =IFERROR(VLOOKUP(D16,'Рубрики'!$B$5:$H$8,7,FALSE),"") | Q16: =IF(E16="","",IF(E16>=P16,"✅ так","❌ ні"))
... A20: 16 | B20: ='Сценарії'!B20 | C20: ='Сценарії'!F20 | D20: ='Сценарії'!E20 | N20: =IF(E20>0,(H20+I20+J20+K20)/E20,"") | O20: =IF(E20>0,K20/E20,"") | P20: =IFERROR(VLOOKUP(D20,'Рубрики'!$B$5:$H$8,7,FALSE),"") | Q20: =IF(E20="","",IF(E20>=P20,"✅ так","❌ ні"))
C22: Підсумок по рубриках
C23: Рубрика | D23: Опубліковано | E23: Сер. перегляди | F23: Сер. ER | G23: Сер. поширення
C24: ='Рубрики'!B5 | D24: =COUNTIFS($D$5:$D$20,C24,$E$5:$E$20,">0") | E24: =IFERROR(AVERAGEIFS($E$5:$E$20,$D$5:$D$20,C24,$E$5:$E$20,">0"),"") | F24: =IFERROR(AVERAGEIFS($N$5:$N$20,$D$5:$D$20,C24,$E$5:$E$20,">0"),"") | G24: =IFERROR(AVERAGEIFS($O$5:$O$20,$D$5:$D$20,C24,$E$5:$E$20,">0"),"")
C25: ='Рубрики'!B6 | D25: =COUNTIFS($D$5:$D$20,C25,$E$5:$E$20,">0") | E25: =IFERROR(AVERAGEIFS($E$5:$E$20,$D$5:$D$20,C25,$E$5:$E$20,">0"),"") | F25: =IFERROR(AVERAGEIFS($N$5:$N$20,$D$5:$D$20,C25,$E$5:$E$20,">0"),"") | G25: =IFERROR(AVERAGEIFS($O$5:$O$20,$D$5:$D$20,C25,$E$5:$E$20,">0"),"")
C26: ='Рубрики'!B7 | D26: =COUNTIFS($D$5:$D$20,C26,$E$5:$E$20,">0") | E26: =IFERROR(AVERAGEIFS($E$5:$E$20,$D$5:$D$20,C26,$E$5:$E$20,">0"),"") | F26: =IFERROR(AVERAGEIFS($N$5:$N$20,$D$5:$D$20,C26,$E$5:$E$20,">0"),"") | G26: =IFERROR(AVERAGEIFS($O$5:$O$20,$D$5:$D$20,C26,$E$5:$E$20,">0"),"")
C27: ='Рубрики'!B8 | D27: =COUNTIFS($D$5:$D$20,C27,$E$5:$E$20,">0") | E27: =IFERROR(AVERAGEIFS($E$5:$E$20,$D$5:$D$20,C27,$E$5:$E$20,">0"),"") | F27: =IFERROR(AVERAGEIFS($N$5:$N$20,$D$5:$D$20,C27,$E$5:$E$20,">0"),"") | G27: =IFERROR(AVERAGEIFS($O$5:$O$20,$D$5:$D$20,C27,$E$5:$E$20,">0"),"")
